# 들어가면서  
> **목표 :** 자바의 예외 처리에 대해 학습하세요.     
        
[1. 프로그램의 에러](#프로그램의-에러)      
[2. Exception과 Error의 차이](#exception과-error의-차이)           
[3. 자바가 제공하는 예외 계층 구조](#자바가-제공하는-예외-계층-구조)               
[4. RuntimeException과 Exception](#runtimeexception과-exception)         
[5. 자바에서 예외 처리 방법](#자바에서-예외-처리-방법)                  
[6. 커스텀 예외 클래스](#커스텀-예외-클래스)              
[7. 클린코드에서의 예외처리](#클린코드에서의-예외처리)       
[8. 도움이 될 만한 자료들](#도움이-될-만한-자료들)           
   
# 프로그램의 에러   
프로그램이 실행 중 어떤 원인에 의해서 오작동하거나 비정삭적으로 종료되는 경우가 있다.   
이러한 결과를 초래하는 원인을 프로그램 **에러** 또는 **오류**라고 말한다.      
           
에러는 대표적으로 3가지로 나눌 수 있다.    
        
1. **컴파일 에러 :** 컴파일 시에 발생하는 에러      
2. **런타임 에러 :** 런타임 시에 발생하는 에러       
3. **논리적 에러 :** 실행은 되지만, 의도와 다르게 동작하는 것        

이 외에도 **우리가 아직 발견하지 못한 에러가 존재할 수도 있다.**       
        
프로그램을 개발하고 실행하는 과정 전반에 걸쳐 우리는 무수히 많은 에러를 접할 수 밖에 없다.             
**'에러가 없는 `100%` 완벽한 프로그램은 없다.'** 라는 말이 있다.         
우리는 **프로그램에서 발생할 수 있는 에러의 경우의 수를 고려하여 이에 대한 대비를 해야한다.**         
      
# Exception과 Error의 차이                 
자바에서는 런타임에 발생할 수 있는 오류를 **에러**와 **예외**로 구분한다.                
              
**에러**                 
<img width="1398" alt="스크린샷 2021-01-13 오후 10 41 20" src="https://user-images.githubusercontent.com/50267433/104459801-98436e00-55f0-11eb-8626-9b633b97f0f9.png"> 
  
     
```java
public class ForError {
    public static void main(String[] args) {
        recursion();
    }
    public static void recursion(){
        System.out.println(111111);
        recursion();
    }
}
```
메모리 부족이나, 스택오버플로우와 같이 발생하면 복구할 수 없는 심각한 오류로,          
코드로 수습할 수 없어 프로그램의 비정상적인 종료를 막을 수 없다.          
프로그래머의 잘못된 코드로 인해 발생하는 경우가 대부분이지만, 간혹 HW 문제로 발생하기도 한다.   
         
**예외**     
<img width="1399" alt="스크린샷 2021-01-14 오후 8 45 16" src="https://user-images.githubusercontent.com/50267433/104586895-75c15b80-56a9-11eb-8f67-e27da9be0d5b.png">  

       
```java
package study;


public class ForException {
    private static String returnString() {
        return null;
    }

    public static void main(String[] args) {
        String getSentence = returnString();
        if(getSentence.equals("Hello World!")){
            System.out.println(getSentence);
        }
    }
}
```
정상적이지 않은 상황을 의미하며, 발생하더라도 수습될 수 있는 비교적 덜 심각한 오류로,                   
예외에 대한 적절한 코드를 미리 작성해 놓으면 프로그램의 비정상적인 종료를 막을 수 있다.              
단, 예외 또한 프로그램에 있어 충분히 위험하고 **발생시키지 않도록 노력하는 것이 중요하다.**            
   
# 자바가 제공하는 예외 계층 구조       
<img width="723" alt="스크린샷 2021-01-14 오후 8 52 26" src="https://user-images.githubusercontent.com/50267433/104587580-70184580-56aa-11eb-847d-624eb03e65cd.png">  

     
출처 : https://examples.javacodegeeks.com/java-throw-exception-example/                
`너무나 완벽한 이미지여서 참고했고 IllegalArgumentException를 추가했다.`      
    
자바에서는 실행 시 발생할 수 있는 오류(Exception/Error)를 클래스로 정의했다.   
모든 오류 클래스는 조상으로 `Throwable` 클래스를 가지고 있다.      
예외 처리시 자주 사용되는 `printStackTrace()`메서드도 `Throwable` 클래스 안에 있다.     

# RuntimeException과 Exception       
    
<img width="723" alt="스크린샷 2021-01-14 오후 9 36 16" src="https://user-images.githubusercontent.com/50267433/104591802-904b0300-56b0-11eb-83d4-b68b8e7ef16a.png">

     
Exception(예외) 클래스들은 크게 2분류로 나뉜다.       
    
1. **RuntimeException 클래스 :** RuntimeException 클래스와 자손들           
2. **Exception 클래스 :** RuntimeException을 제외한 Exception 클래스와 자손들
    
**RuntimeException 클래스**   
* RuntimeException 클래스들은 주로 프로그래머의 실수에 의해 발생될 수 있는 예외들이다.      
* 주로 자바 프로그래밍 요소들과 관계가 깊다.          
  * ArrayIndexOutOfBoundsException
  * NullPointerException
  * ClassCastException
  * ArithmeticException
  * 기타 등등
    
**Exception 클래스**     
* Exception 클래스들은 주로 외부의 영향으로 발생할 수 있는 예외들이다.            
* 프로그램의 사용자들의 동작에 의해서 발생하는 경우가 많다.         
  * FileNotFoundException    
  * ClassNotFoundException     
  * DataFormatException     

이런 `RuntimeException`/`Exception` 클래스는 프로그래밍 방법에서도 차이를 보인다.          
`Exception 클래스`들은 `Checked Exception`으로 무조건 예외처리를 해줘야한다.       
`RuntimeException 클래스`들은 `Unchecked Exception`으로 예외처리를 생략해도 된다.   
     
||Checked Exception|Unchecked Exception|   
|-|-----------------|-------------------|       
|처리 여부|반드시 예외를 처리해야 함|명시적인 처리를 강제하지 않음|  
|확인 시점|컴파일 단계|실행 단계|     
|대표 예외|**Exception의 상속받는 하위 클래스 중**<br> **Runtime Exception을 제외한 모든 예외**<br> * IOException<br>* SQLException|**Runtime Exception 하위 예외**<br>* NullPointerException<br>* IllegalArgumentException<br>* IndexOutOfBoundException<br>* SystemException|  
    
# 자바에서 예외 처리 방법    
   
**예외 처리 :**                   
프로그램 실행 시 발생할 수 있는 '예외'의 발생에 대비한 코드를 작성하는 것으로                         
실행 중인 프로그램의 갑작스런 비정상 종료를 막고, 실행 상태를 유지할 수 있도록 해준다.        
     
발생한 예외를 처리하지 못하면 프로그램은 비정상적으로 종료되며,         
처리되지 못한 예외는 JVM의 예외처리기가 받아서 예외의 원인을 화면에 출력한다.        
   
## try ~ catch     
예외를 처리하는 방식으로 `try-catch 문`이 있다.     
      
```java
try {
    ... 관찰 영역...   
}
catch(Exception name) {
    ... 처리 영역...  
}     
```
```java
public class ExceptionStudy {
    public static void main(String[] args) {
        Scanner kb = new Scanner(System.in);

        try {
            System.out.print("a/b...a? ");
            int n1 = kb.nextInt();
            System.out.print("a/b...b? ");
            int n2 = kb.nextInt();
            System.out.printf("%d / %d = %d \n", n1, n2, n1 / n2);    // 예외 발생 지점
        } catch (ArithmeticException e) {
            System.out.println(e.getMessage());
        }

        System.out.println("Good bye~~!");
    }
}
// 참고로 정수를 0으로 나누는 것은 예외가 발생하지만,    
// 실수를 0으로 나누는 것은 예외가 발생하지 않는다.    

/* 실행 결과
 / by zero
 Good bye~~!
 */
```     
`try 영역`에서 발생한 얘외 상황을 `catch 영역`에서 처리한다.        
                         
`try 영역`의 실행 중간에 예외 상황이 발생하면 JVM은 예외에 알맞은 '예외 객체'를 생성한다.                               
'예외 객체'는 `catch 구문`의 매개변수에 전달되면서 `catch 구문`안에서 예외 처리를 진행한다.             
참고로, `catch 구문`이 수행되면 내부 로직은 상관없이 JVM에서는 예외 처리가 된 것으로 간주한다.        
          
**try-catch문 흐름**         
`try-catch 문`에서는, 예외가 발생한 경우와 발생하지 않았을 때의 흐름이 달라진다.   
   
* **try블럭 내에서 예외가 발생하지 않은 경우**      
  * `catch 블럭`을 거치지 않고 전체 `try-catch문`을 빠져나가서 수행을 계속한다.    
<img width="723" alt="스크린샷 2021-01-15 오후 12 30 23" src="https://user-images.githubusercontent.com/50267433/104677831-7a2f5800-572d-11eb-906c-8055effbde0a.png">  
   
     
* **try블럭 내에서 예외가 발생한 경우**      
  * 발생한 예외와 일치하는 `catch 문`이 있는지 확인한다.
  * 일치하는 `catch 문`을 찾게되면, 그 `catch 문`을 실행하고 프로그램 실행을 계속한다.         
  * 일치하는 `catch 문`이 없다면 예외 처리가 되지 않아 프로그램이 종료된다.        
    
<img width="723" alt="스크린샷 2021-01-15 오후 12 28 00" src="https://user-images.githubusercontent.com/50267433/104677759-5704a880-572d-11eb-901f-5353654240c6.png">  

  
**try의 범위**    
`try 문` 내에서 예외가 발생하면 `catch 문`으로 '실행 흐름'이 바뀐다.                 
이로인해, 예외가 발생한 코드보다 아래에 존재하는 코드들은 실행이 되지 않는다.             
그렇기 때문에 우리는 `try 문`의 범위를 알맞게 설정하도록 노력해야 한다.          
	    
그렇다면 우리는 어떠한 기준으로 `try 문`의 범위를 설정을 해야할까?     
`try 문`의 범위는 트랜젝션과 비슷하게 하나의 실행 작업을 묶어주는 범위로 설정한다.     

```java
public class ExceptionStudy {
    public static void main(String[] args) {
        Scanner kb = new Scanner(System.in);
        System.out.print("a/b...a? ");
        int n1 = kb.nextInt();						// 입력 오류 발생
        System.out.print("a/b...b? ");
        int n2 = kb.nextInt();						// 입력 오류 발생
        System.out.printf("%d / %d = %d \n", n1, n2, n1 / n2);    	// 예외 발생 지점
    }
}
```    
2개의 값을 입력받고 이를 출력하는 코드이다.        
여기서 각각의 기능은 무엇이며 try에 대한 범위를 어떻게 설정하는지 다뤄볼 예정이다.       
참고로 여러 Java 책에 있는 내용과 다르게 필자의 생각을 정리하여 서술해보겠다.            
        
**하나의 작업에 하나의 try-catch**     
```java
public class ExceptionStudy {
    public static void main(String[] args) {
        Scanner kb = new Scanner(System.in);
        try {
	    System.out.print("a/b...a? ");
            int n1 = kb.nextInt();						// 입력 오류 발생
	} catch (InputMismatchException e) {
	    System.out.println(e.getMessage());
	}
	
        try {
	    System.out.print("a/b...b? ");
            int n2 = kb.nextInt();						// 입력 오류 발생
	} catch (InputMismatchException e) {
	    System.out.println(e.getMessage());
	}
	
	try {
	    System.out.printf("%d / %d = %d \n", n1, n2, n1 / n2);    		// 예외 발생 지점
	} catch (ArithmeticException e) {
	    System.out.println(e.getMessage());
	}
    }
}
```       
앞서 `try 문`의 범위는 하나의 실행 작업이라 표현했기에           
위 예제에서 입력 작업 2번을 각각의 `try-catch`로 처리해야 한다고 생각할 수 있다.          
이는 맞는 생각이고 맞는 말이며 한 가지 기능에 하나의 `try-catch`를 사용하는 것은 정당하다.         
      
      
```java
public class ExceptionStudy {
    public static void main(String[] args) {
        Scanner kb = new Scanner(System.in);
	
        try {
	    System.out.print("a/b...a? ");
            int n1 = kb.nextInt();
	    System.out.print("a/b...b? ");
            int n2 = kb.nextInt();		
	    System.out.printf("%d / %d = %d \n", n1, n2, n1 / n2); 
	} catch (InputMismatchException | ArithmeticException e) {
	    System.out.println(e.getMessage());
	}
    }
}
```   
하지만, 책에서는 모든 코드들도 출력을 위해 필요한 것들이므로 하나의 작업이라 말한다.   
이 말에 대해서 필자는 또 맞는 생각이라고 말하고 싶다.     
       
이상하다고 느낄 수 있다.         
각 기능을 `try-catch 문`으로 표현된 코드도 맞다 하고       
하나의 큰 `try-catch 문`으로 표현한 코드다 맞다 했으니 말이다.   
             
클린 코드에서 말하기 함수는 한 가지 기능만 수행해야 말한다.        
여기서 말하는 한 가지 기능이란, 추상적 개념으로 딱 한 가지 기능을 수행하는 것을 의미한다.     
즉, 위 코드에서는 입력 기능, 출력 기능이 있고 아래와 같은 코드로 변경해보겠다.        

```java
public class ExceptionStudy {
    public static void main(String[] args) {
        Scanner kb = new Scanner(System.in);
        try {
            int n1 = inputIntValueByScanner(kb);
            int n2 = inputIntValueByScanner(kb);
            printOperandAndResult(n1, n2);
        } catch (InputMismatchException | ArithmeticException e) {
            System.out.println(e.getMessage());
        }
    }

    public static int inputIntValueByScanner(Scanner kb) throws InputMismatchException{
        return kb.nextInt();
    }
    public static void printOperandAndResult(int n1, int n2) throws ArithmeticException{
        System.out.printf("%d / %d = %d \n", n1, n2, n1 / n2);
    }

}
```
사실, `n1` 과 `n2` 값을 입력하는 부분은 이전 그대로 사용해도 되지만,        
손쉬운 설명을 위해 메서드를 새롭게 정의를 해보았다.        
        
메서드를 보면 추상적인 한 가지 작업만을 수행하는 것을 알 수 있다.            
데이터를 입력 받거나, 원하는 계산법으로 출력을 하는 경우이다.          
그리고 각각의 메서드는 알맞은 예외 클래스를 호출한 영역으로 던지고 있다.   
            
그럼 이제 `main()`이 수행하는 작업이 무엇인지 알 수 있다.                  
바로 `입력+출력`을 합친 것으로 쉽게 표현하면 '입출력 관리'작업이다.           
이 개념도 어려우면 단위 모듈을 합친 복합 모듈이라 생각하면 이해하기 편할 것이다.     
        
`main()`도 사실은 각각의 작업들을 합친 상위 개념의 작업이다.      
그렇기 때문에, `main()`에서 `try{}`를 사용하여 예외를 처리한 것이다.   
      
다시 한번 말하지만 `try-catch`는 하나의 작업에 대해서 묶어주는 범위로 지정하는 것이 좋다.           
하지만, 클린코드를 모르거나, 아무 생각없이 공부했다면 명확이 이해하지 못했을 가능성이 높다.             
위 코드도 마찬가지이다.           
함수가 여러 작업을 한 번에 처리하기에 '하나의 작업'에 대해서 이해하기 어려웠다.                  
하지만, 클린코드를 모르거나, 아무 생각없이 공부했다면 명확이 이해하지 못했을 가능성이 높다.                
그렇기 때문에 클린코드가 필요한 것이고 클린 코드를 통해 하나의 작업을 예외처리 범위로 지정하자.                    
       
**catch 문의 괄호`()`**      
```java
public class ExceptionStudy {
    public static void main(String[] args) {
        Scanner kb = new Scanner(System.in);

        try {
            System.out.print("a/b...a? ");
            int n1 = kb.nextInt();
            System.out.print("a/b...b? ");
            int n2 = kb.nextInt();
            System.out.printf("%d / %d = %d \n", n1, n2, n1 / n2);    // 예외 발생 지점
        } catch (Exception e) {
            System.out.println(e.getMessage());
        }

        System.out.println("Good bye~~!");
    }
}
```
`catch 문`의 괄호`()`에는 예외클래스 타입과 참조변수를 기술한다.                
`catch 문`의 괄호`()`는 메서드의 매개변수와 마찬가지로 하위 예외 객체를 인자로 받을 수 있다.          
그렇기에 `Exception` 클래스 타입의 참조변수를 지정하면 모든 예외를 처리할 수 있다.            
하지만, 이는 단순히 로직만 돌아가는 것일 뿐이지 코드만 보면 어떤 에러가 발생하는지 알기 어려워진다.           

```java
public class ExceptionStudy {
    public static void main(String[] args) {
        Scanner kb = new Scanner(System.in);

        try {
            System.out.print("a/b...a? ");
            int n1 = kb.nextInt();
            System.out.print("a/b...b? ");
            int n2 = kb.nextInt();
            System.out.printf("%d / %d = %d \n", n1, n2, n1 / n2);    // 예외 발생 지점
        } catch (ArithmeticException e) {
            System.out.println(e.getMessage());
        }

        System.out.println("Good bye~~!");
    }
}
```
코드는 명확해야한다.    
프로그램을 실행시키지 않아도 어떤 로직이 수행되는지 동료와 함께 파악할 수 있어야한다.      
그렇기에 명확한 예외클래스를 정의하는 습관을 가지도록 노력하자.    
       
**참조 변수 중복**           
`catch 문` 안에 예외처리를 해야할 코드가 존재한다면 `try-catch 문`을 작성할 수 있다.          
이 때 `catch 변수의 명`을 이미 선언된 `catch 변수의 명`으로 사용하면 컴파일 에러가 발생한다.     
   
<img width="1021" alt="스크린샷 2021-01-17 오전 11 27 56" src="https://user-images.githubusercontent.com/50267433/104829458-66176200-58b7-11eb-90d7-3019f444f292.png">   

   
```java
public class ExceptionStudy {
    public static void main(String[] args) {
        Scanner kb = new Scanner(System.in);

        try {
            System.out.print("a/b...a? ");
            int n1 = kb.nextInt();
            System.out.print("a/b...b? ");
            int n2 = kb.nextInt();
            System.out.printf("%d / %d = %d \n", n1, n2, n1 / n2);      // 예외 발생 지점
        } catch (ArithmeticException e) {
            try {
                System.out.println(e.getMessage());
            } catch (InputMismatchException e) {			// 컴파일 에러 발생 지점 
                System.out.println(e.getMessage());
            }
        }

        System.out.println("Good bye~~!");
    }
}
```
이미 사용하고 있는 변수의 명을 다시 사용하지 않도록 하자         
       
      
**다중 catch 문**        
```java
public class ExceptionStudy {
    public static void main(String[] args) {
        Scanner kb = new Scanner(System.in);

        try {
            System.out.print("a/b...a? ");
            int n1 = kb.nextInt();
            System.out.print("a/b...b? ");
            int n2 = kb.nextInt();
            System.out.printf("%d / %d = %d \n", n1, n2, n1 / n2);    // 예외 발생 지점
        } catch (ArithmeticException e) {
            System.out.println(e.getMessage());
        }

        System.out.println("Good bye~~!");
    }
}
```
이전부터 계속 제시되었던 이 코드는 사실 2가지 에러를 발생시킬 수 있다.   
        
1. ArithmeticException        
2. InputMismatchException     
        
JDK 7부터 하나의 `try 문`에 여러 `catch 문`을 사용할 수 있게 되었다.           
그렇기 때문에 위와 같은 코드도 `다중 catch 문`을 이용해서 한 번에 처리할 수 있다.   

```java
public class ExceptionStudy {
    public static void main(String[] args) {
        Scanner kb = new Scanner(System.in);

        try {
            System.out.print("a/b...a? ");
            int n1 = kb.nextInt();
            System.out.print("a/b...b? ");
            int n2 = kb.nextInt();
            System.out.printf("%d / %d = %d \n", n1, n2, n1 / n2);    // 예외 발생 지점
        } catch (ArithmeticException e) {
            System.out.println(e.getMessage());
        } catch (InputMismatchException e) {
            System.out.println(e.getMessage());
        }

        System.out.println("Good bye~~!");
    }
}
```
* `catch 문`을 한번 더 사용해서 처리를 해주었다.        
        
만약에 처리해야할 예외 클래스 많다면 어떻게 될까?             
사실 그런 경우 클래스의 설계가 잘못된 것이지만, 이를 생략하고 따져보겠다.         
모든 `catch 문`을 사용해줘야 할까? **맞다.**      
하지만, 이를 조금 줄일 수 있는 방법이 있다.      

```java
public class ExceptionStudy {
    public static void main(String[] args) {
       Scanner kb = new Scanner(System.in);
   
       try {
          System.out.print("a/b...a? ");
          int n1 = kb.nextInt();
          System.out.print("a/b...b? ");
          int n2 = kb.nextInt();
          System.out.printf("%d / %d = %d \n", n1, n2, n1 / n2);    // 예외 발생 지점
       }
       catch(ArithmeticException | InputMismatchException e) {
          System.out.println(e.getMessage());
       }
   
       System.out.println("Good bye~~!");
    }
}
```
* `|`를 사용해서 하나의 `catch 문`에서 여러 예외 클래스를 처리하게 만들었다.              
* 당연한 얘기지만, 동일한 예외처리 로직을 실행할 때 `|`를 사용해서 묶어줘야 한다.           

하지만, 다중 `catch 문`이 모든 상황에서 사용되는 것은 아니다.     
   
<img width="1045" alt="스크린샷 2021-01-16 오후 8 42 50" src="https://user-images.githubusercontent.com/50267433/104810949-7853ba80-583b-11eb-84a3-456c2af90fe4.png">  

  
   
```java
public class ExceptionStudy {
    public static void main(String[] args) {
        Scanner kb = new Scanner(System.in);

        try {
            System.out.print("a/b...a? ");
            int n1 = kb.nextInt();
            System.out.print("a/b...b? ");
            int n2 = kb.nextInt();
            System.out.printf("%d / %d = %d \n", n1, n2, n1 / n2);    	// 예외 발생 지점
        } catch (Exception e) {						
            System.out.println(e.getMessage());
        } catch (InputMismatchException e) {				// 컴파일 에러 발생 
            System.out.println(e.getMessage());
        }

        System.out.println("Good bye~~!");
    }
}
```
* `InputMismatchException` 에서 에러가 생겼다.       
* 컴파일 에러 메시지를 읽어보면 이미 예외를 잡았다는 메시지가 나온다.    
            
`catch 문`에서는 예외 클래스들간의 계층 구조를 따져 사용을 제한한다.                   
즉, 상위 예외 클래스가 이미 기술되었다면 하위 예외 클래스는 사용할 수 없다는 뜻이다.        
이는 `'|' 를 이용한 다중 catch 문` 에서도 마찬가지이다.      
           
<img width="1051" alt="스크린샷 2021-01-16 오후 9 01 31" src="https://user-images.githubusercontent.com/50267433/104811354-28c2be00-583e-11eb-9c5c-ac90ec9e4985.png">   


           
```java
public class ExceptionStudy {
    public static void main(String[] args) {
        Scanner kb = new Scanner(System.in);

        try {
            System.out.print("a/b...a? ");
            int n1 = kb.nextInt();
            System.out.print("a/b...b? ");
            int n2 = kb.nextInt();
            System.out.printf("%d / %d = %d \n", n1, n2, n1 / n2);      // 예외 발생 지점
        } catch (Exception  | InputMismatchException e) {		// 컴파일 에러 발생  
            System.out.println(e.getMessage());
        } 

        System.out.println("Good bye~~!");
    }
}
```

앞서 말했듯이, 상위 예외 클래스가 이미 기술되었다면 하위 예외 클래스는 사용할 수 없다.   
하지만 이러한 원칙은 '예외 클래스의 지정된 순서'에 기안하여 일어나는 경우이다.
즉, 상위 클래스가 나중에 기술된다면 컴파일 에러가 발생하지 않는다.   

<img width="1057" alt="스크린샷 2021-01-16 오후 9 07 19" src="https://user-images.githubusercontent.com/50267433/104811459-ee0d5580-583e-11eb-96a6-9438f224afdb.png">  


```java
public class ExceptionStudy {
    public static void main(String[] args) {
        Scanner kb = new Scanner(System.in);

        try {
            System.out.print("a/b...a? ");
            int n1 = kb.nextInt();
            System.out.print("a/b...b? ");
            int n2 = kb.nextInt();
            System.out.printf("%d / %d = %d \n", n1, n2, n1 / n2);    // 예외 발생 지점
        } catch (InputMismatchException e){
            System.out.println(e.getMessage());
        } catch (Exception e) {
            System.out.println(e.getMessage());
        }

        System.out.println("Good bye~~!");
    }
}
```
* `InputMismatchException` 이후에 `Exception` 예외처리를 진행했고 문제가 없다.  


<img width="1023" alt="스크린샷 2021-01-16 오후 9 07 50" src="https://user-images.githubusercontent.com/50267433/104811496-36c50e80-583f-11eb-9568-c0d11349bb49.png">    

  
```java
public class ExceptionStudy {
    public static void main(String[] args) {
        Scanner kb = new Scanner(System.in);

        try {
            System.out.print("a/b...a? ");
            int n1 = kb.nextInt();
            System.out.print("a/b...b? ");
            int n2 = kb.nextInt();
            System.out.printf("%d / %d = %d \n", n1, n2, n1 / n2);      // 예외 발생 지점
        } catch (InputMismatchException | Exception e) {		// 컴파일 에러 발생 
            System.out.println(e.getMessage());
        }

        System.out.println("Good bye~~!");
    }
}
```
단, `'|'를 이용한 다중 catch 문` 처리는 동일한 순서로 처리한다고 가정하기에     
상위 예외 클래스와 하위 예외클래스를 동시에 사용하면 컴파일 에러가 발생한다.        
    
`다중 catch 문`은 이미 선언된 클래스의 계층 구조를 따져 추가될 클래스에 제한을 둔다.   
그렇기에 예외 처리를 할 때 예외 클래스간의 계층 관계를 생각하면서 기술하자.     
     
## throw            
`throw` 키워드를 사용하면 프로그래머가 고의로 예외를 발생시킬 수 있다.       
      
**방법**    
1. 연산자 new를 이용해서 발생시키려는 얘외 클래스를 만든다.       
2. `trhow`를 이용해서 예외를 발생시킨다.    

```java
class UserException extends Exception { }

public class ExceptionStudy {
    public static void main(String[] args) {
        try {
            System.out.println("여기는 사용자 정의 에러로 처리해야합니다.");
            throw new UserException();
        } catch (UserException e) {
            System.out.println(e.getMessage());
        }
    }
}
```
   
프로그래머가 고의로 예외 클래스의 객체를 만들어 예외를 발생시킬 수 있다.                
예외가 발생되면 `try-catch`문으로 처리하거나 `throw`로 던져야 하며             
주로, 사용자가 정의한 예외 클래스를 특정 시점에 객체로 만들어 예외를 발생시킬 때 사용한다.       
        
```java
       Board board = BoardRepository.findById(id).orElseThrow(() -> new
                IllegalArgumentException("해당 게시판 아이디가 없습니다. id=" + id));
```   
필자 같은 경우는 `JpaRepository`에서 반환된 `Optional<>` 클래스에서     
`orElseThrow()` 메서드를 통해 반환된 객체가 없다면 에러를 발생시키도록 정의하기도 했다.       
    
## throws       
예외가 발생하면 예외가 발생한 영역은 예외처리에 대한 책임을 가지게 된다.                             
하지만, 꼭 해당 영역에서만 예외처리를 진행하지는 않아도 된다.               
`throws` 키워드를 통해 자신을 호출한 영역으로 예외처리에 대한 책임을 전가할 수 있다.        
        
즉, 현재 영역에서 `try-catch 문` 예외처리를 진행하는 것이 아니라      
자신을 호출한 영역에서  `try-catch 문`으로 예외를 처리하게끔 만들 수 있다.   
   
```java
public class ExceptionStudy {
    public void catchIOException() {
        try {
            a();
        } catch (IOException e) {
            System.out.println(e.getMessage());
        }
    }

    public void a() throws IOException {
        aa();
    }

    public void aa() throws IOException {
        aaa();
    }

    public void aaa() throws IOException {
        FileInputStream stream = new FileInputStream("sectionName"); 
        stream.close();
    }
}
```
* `throws` 는 자신을 호출한 영역에 에외처리에 대한 책임을 전가할 수 있다.         
* `aaa()` -> `aa()` -> `a()` -> `catchIOException()` 순으로 책임이 전가되었다.           
* 만약 `catchIOException()`에서도 `throws`를 사용한다면 프로그램이 종료될 것이다.       
  * 예외처리를 JVM/OS에 넘기는 것이므로 사실상 예외처리가 진행되지 않은 것과 동일하다.    
           
위 코드는 클린코드에서 소개된 예제중 하나로           
이 같은 방법을 사용하면 메서드 이곳 저곳에서 예외처리를 진행하는 것이 아니라           
상위 메서드에서 예외를 처리한다는 사용자 기준을 만들게 되어 코드가 깔끔해진다.         
또한, 여러 예외들을 상위 메서드에서 처리해 사용자가 지정한 예외로 넘길 수도 있다.    
   
단, 상위 메서드와 하위 메서드의 예외처리 결합이 강해지므로       
하위 메서드의 얘외에 대한 사항이 변경되면 상위 모든 메서드가 영향을 받는 문제점이 있다.     
그러니 적절한 상황에 알맞게 사용하도록 생각하고 주의해야한다.    
          
## finally   
`try-catch 문`을 작성하다 보면 프로그램이 종료되어도 무조건 실행해야 하는 코드들이 존재한다.           
예를 들면, `BufferedWriter`의 `close()`나 `Connection`의 `close()`등이 있다.           
만약, `close()`를 사용하지 않는다면 애플리케이션이 종료되어도 관련 프로그램은 여전히 살아있다.        
      
하지만, `close()`라는 것은 보통 로직의 마지막에 오는 경우가 대다수이다.            
만약 프로그램이 `try 문`에서 실행되다가 `close()`가 오기전에 예외가 발생한다면 어떻게 될까?        
그렇다면 `close()`는 실행되지 않고 `catch 문`으로 실행 흐름이 넘어갈 것이다.            
그렇다고 `catch 문` 안에다 `close()`를 넣어도 예외가 발생하지 않으면 실행하지 않게 된다.       
이 같은 문제를 해결하기 위해 등장한 것이 `finally 문`이다.       

```java
class UserException extends Exception { }

public class ExceptionStudy {
    public static void main(String[] args) {
        Path filePath = Paths.get("URL 경로");
        BufferedWriter writer = null;

        try {
            writer = Files.newBufferedWriter(filePath);
            writer.write('a');
            writer.write('z');
        } catch (IOException e) {
            e.printStackTrace();
        } finally {
            try {
                if (writer != null) {
                    writer.close();
                }
            } catch (IOException e) {
                e.printStackTrace();
            }

        }

    }
}
```   
`finally 문`을 사용했기에 예외가 발생하든, 안하든 사용된 자원을 반환할 수 있게 되었다.      
또한, `finally 문` 안에서도 `try-catch 문`을 사용할 수 있다.           
하지만, 코드를 보면서 느끼는 점은 복잡성이 커지고 가독성이 안 좋은걸 알 수 있다.    
또한, 한 가지가 아닌 여러개의 `finally`와 `예외`가 존재할 경우 더 심할 것을 예상할 수 있다.        
추가로 개발자가 매번 `close()`를 신경써야 하고 이를 까먹을 수 있다는 문제도 있다.    
      
이러한 문제점을 해결하기 위해 JDK 7 부터 'try-with-resource 문'을 지원하기 시작했다.     
      
## try-with-resource 문      
`try-with-resource 문`은 향상된 `try-catch 문`이다.                       
기존 `finally {}`를 통한 자원 반환을 사용자가 아닌 JVM이 직접 처리해준다.              
(사람들이 헷갈리는게 `finally {}`를 생략하는 것이지 `catch()`를 생략하는 것은 아니다.)       
단, 모든 클래스가 `try-with-resource 문`을 사용할 수 있는 것은 아니다.          
    
**AutoCloseable**    
```java
public interface AutoCloseable {
    void close() throws Exception;
}
```
직/간접적으로 `AutoCloseable` 인터페이스를     
구현한 클래스만 `try-with-resource 문`를 사용할 수 있다.         
	  
**try-with-resource 정의 방법**
```java
try (나중에 해제될 리소스 생성 지역) {

} catch {
}
```    
* 예외처리는 `catch 문`에서 그대로 처리하고 `finally 문`이 사라진 것을 알 수 있다.       
* 일반적인 `try-catch 문`과 달리, `try 문`에 `()`가 들어왔다.       
* `()`안에 해제될 리소스(`BufferedWriter등..`)를 생성하는 구문을 넣어주면 된다.  


**try-with-resource 이용 전**
```java
class UserException extends Exception { }

public class ExceptionStudy {
    public static void main(String[] args) {
        Path filePath = Paths.get("URL 경로");
        BufferedWriter writer = null;

        try {
            writer = Files.newBufferedWriter(filePath);
            writer.write('a');
            writer.write('z');
        } catch (IOException e) {
            e.printStackTrace();
        } finally {
            try {
                if (writer != null) {
                    writer.close();
                }
            } catch (IOException e) {
                e.printStackTrace();
            }

        }

    }
}
```   

**try-with-resource 이용 후**
```java
class UserException extends Exception { }
   
public class ExceptionStudy {
    public static void main(String[] args) {
        Path filePath = Paths.get("URL 경로");
        
        try (BufferedWriter writer = Files.newBufferedWriter(filePath);) {
            writer.write('a');
            writer.write('z');
        } catch (IOException e) {
            e.printStackTrace();
        }
        
    }
}
```    
**try-with-resource 2개 이상의 리소스 사용하기**
```java
class UserException extends Exception { }

public class ExceptionStudy {
    public static void main(String[] args) {
        Path filePath = Paths.get("URL 경로");

        try (
                BufferedWriter writer = Files.newBufferedWriter(filePath);
                FileInputStream file = new FileInputStream(new File("파일 경로"));
        ) {
            writer.write('a');
            writer.write('z');
        } catch (IOException e) {
            e.printStackTrace();
        }

    }
}
```
* 2개 이상의 리소스도 일반적인 코드를 작성하는 것처럼 기술하여 사용할 수 있다.     
* 2개 이상의 리소스를 사용하고자 한다면 `;`를 붙여서 구분을 지어줘야한다.      

**try-with-resource와 바이트코드**       
* **바이트 코드 변환 전**          
     
```java
class MyStream implements Closeable {

    @Override
    public void close() throws RuntimeException {
        System.out.println("MyStream is close");
    }
}

public class ExceptionStudy {
    public static void main(String[] args) {
        try (MyStream myStream = new MyStream()) {
        } finally {
            System.out.println("finally is run");
        }

    }
}
```

* **바이트 코드 변환**    
```java
// 
// Decompiled by Procyon v0.5.36
// 

package study;

public class ExceptionStudy
{
    public static void main(final String[] args) {
        try {
            final MyStream myStream = new MyStream();
            final Throwable t = null;
            if (myStream != null) {
                if (t != null) {
                    try {
                        myStream.close();
                    }
                    catch (Throwable exception) {
                        t.addSuppressed(exception);
                    }
                }
                else {
                    myStream.close();
                }
            }
        }
        finally {
            System.out.println("finally is run");
        }
    }
}
```
    
바이트코드로 변환된 코드를 보면 재미있는 점이 있다.         
사실 `try-with-resource`는 `finally 문`을 대신하는 것이 아니라          
`try 문` 안에 새로운 `try-catch 문`에서 리소스를 종료하고 자원을 해제하는 역할을 한다.             
그 과정에서 `Throwable` 데이터 타입을 이용해 `catch 문`의 가장 마지막 순서에 삽입한다.       
즉, 기존 `try 문` 안에서 `다중 catch 문`을 이용한 전력이라고 볼 수 있다.             
이 방법으로, 기존에 존재하는 `catch 문`과 `finally 문`과의 충돌없이 리소스를 해제한 것이다.          
    
**try-with-resource와 finally**    
```java
class MyStream implements Closeable {

    @Override
    public void close() throws RuntimeException {
        System.out.println("MyStream is close");
    }
}

public class ExceptionStudy {
    public static void main(String[] args) {
        try (MyStream myStream = new MyStream()) {
        } finally {
            System.out.println("finally is run");
        }

    }
}

/* 실행
 MyStream is close
 finally is run
 */
```
`try-with-resource`를 사용해도 `finally 문`은 사용가능하다.                
사실 말이 되는게 `finally 문`에서 꼭 프로그램을 종료하는 코드만 기술해야하는 법은 없기 때문이다.          
동작 순서는 리소스의 자원이 반환된 후 `finally 문`이 마지막으로 실행된다.      
    

**JDK 9에서의 향상된 try-with-resource**
```java
class UserException extends Exception { }

public class ExceptionStudy {
    public static void main(String[] args) {
        Path filePath = Paths.get("URL 경로");
 	BufferedWriter writer = Files.newBufferedWriter(filePath);
        FileInputStream file = new FileInputStream(new File("파일 경로"));
	
        try (writer, file) {
            writer.write('a');
            writer.write('z');
        } catch (IOException e) {
            e.printStackTrace();
        }

    }
}
```   
* JDK 9 부터는 향상된 `try-with-resource`를 지원한다. 
* 기존에 `try()`에 직접 객체를 생성하는 생성문을 기술했던 것과 달리,     
* 외부에서 생성된 객체의 참조변수를 `try()`를 넣는 것만으로 자원 해제를 지원해준다.     
* 또한 참조 변수를 기입하는 것이기에 `;` 대신 `,`를 사용하여 다른 변수들과 구분해준다.    
* 이로써 `try-with-resource`는 우리가 자주 사용하는 코드처럼 구성이 되었다.   
   
  
`try-with-resource 문`을 사용하면 코드에 대한 가독성이 좋아진다.                 
또한, 개발자는 자원 해제에 대해서 생각하지 않아도 되게 되었다.          
그러니 리소스를 반환할 예외처리를 사용할 경우 **적극적으로** 사용하길 권장한다.     

**Lombok @Cleanup 어노테이션**    
```java

import lombok.Cleanup;
import java.io.*;

public class CleanupExample {
  public static void main(String[] args) throws IOException {
    @Cleanup InputStream in = new FileInputStream(args[0]);
    @Cleanup OutputStream out = new FileOutputStream(args[1]);
    byte[] b = new byte[10000];
    while (true) {
      int r = in.read(b);
      if (r == -1) break;
      out.write(b, 0, r);
    }
  }
}
```
코드 작성을 도와주는 롬복(Lombok)에도 `try-with-resource`와 비슷한 기능이 있다.          
바로, `@Cleanup`로 해당 라인에 생성한 리소스를 자동으로 반환해주는 역할을 하고 있다.     

하지만, `AutoCloseable` 인터페이스를 구현한 클래스만 가능한지 공식 문서에서도 나오지 않고       
롬복(Lombok) 자체도 Java의 순수 기능이 아니기에 의존적인 사용은 지양한다.   
       
# 커스텀 예외클래스      
Java에서 지원하는 예외클래스 외에도 사용자가 정의한 예외클래스를 사용할 수 있다.         

```java
class [클래스 이름] extends Exception {}
```
```java
class UserException extends Exception { }
```
방법은 간단하다. **`extends` 를 통해 `Exception` 클래스를 상속받으면 된다.**      
그리고 필요하다면 변수나 메서드를 추가해도 된다.    

```java
class UserException extends Exception { 
    super("유효하지 않은 나이가 입력되었습니다."); 
}
```
`super()`를 통해 `Exception`을 사용하지만 메시지를 다르게 줄 수 있다.    
      
   
**커스텀 예외클래스 사용하기**
```java
class UserException extends Exception { }

public class ExceptionStudy {
    public static void main(String[] args) {
        try {
            System.out.println("여기는 사용자 정의 에러로 처리해야합니다.");
            throw new UserException();
        } catch (UserException e) {
            System.out.println(e.getMessage());
        }
    }
}
```
Java에서 기본으로 제공하는 예외클래스들은 객체화되는 이벤트가 존재한다.         
그러나, 사용자가 정의한 예외클래스는 이벤트가 정해져있지 않으므로 이를 정의해줘야한다.         
즉, 사용자가 정의한 예외 클래스는 `throw`와 같이 사용해야한다.        
       
**RuntimeException 커스텀 예외클래스 사용하기**
```java
class UserException extends RuntimeException { }

public class ExceptionStudy {
    public static void main(String[] args) {
            System.out.println("여기는 사용자 정의 에러로 처리해야합니다.");
            throw new UserException();
    }
}
```   
최근에는 무조건 명시적으로 예외처리를 해줘야 하는 `Exception` 대신에,               
선택적으로 예외처리를 할 수 있는 `RuntimeException`을 상속 받고 있다.           
            
**커스텀 예외 클래스를 만들 때 참고사항**        
* **Always Provide a Benefit :**             
자바에서 제공하는 표준 예외 클래스는 다양한 장점을 가진 기능들이다.            
JDK가 제공하고 있는 예외 클래스에 비해 커스텀 에외 클래스가 어떠한 장점도 제공하지 못한다면?          
커스텀 예외를 만드는 이유를 다시 생각해볼 필요가 있다.        
즉, 이미 JDK에서 제공하고 있는 예외라면 이를 적극적으로 활용하는 것이 좋다.       
물론, 이보다 더 뛰어난 퍼포먼스를 제공할 수 있으면 커스텀 예외 클래스를 생성하는 것이 좋다.   

* **Follow the Naming Convention :**
JDK가 제공하는 예외 클래스들은 대부분 `Exception` 으로 끝나는 것을 알 수 있다.
이러한 네이밍 규칙은 자바 생태계 전체에 사용되는 규칙이다.
즉, 만들고자 하는 커스텀 예외 클래스도 이 네이밍 규칙을 따르는 것이 좋다.    
   
* **Provide javadoc Comments for Your Exception Class :**       
어떠한 javadoc 코멘트도 없이 만들어진 커스텀 예외들이 있다.              
API의 모든 클래스, 멤버변수, 생성자들에 대해서는 문서화 하는 것은 '좋은 자세'이다.                
문서화되지 않은 API들은 사용하기 매우 어렵기 때문이다.                    
JavaDoc은 예외가 발생할 수도 있는 상황과 예외의 일반적인 의미를 기술하여        
다른 개발자들이 API를 이해하고 일반적인 에러상황들을 피하도록 도와준다.         
    
```java
/**
 * The MyBusinessException wraps all checked standard Java exception and enriches them with a custom error code.
 * You can use this code to retrieve localized error messages and to link to our online documentation.
 * 
 * @author TJanssen
 */
public class MyBusinessException extends Exception { ... }
```
  
* **Provide a Constructor That Sets the Cause :**        
`catch`된 표준 예외 클래스들은 발생한 오류를 분석하는데 필요한 중요한 정보를 포함한다.      
그렇기 때문에, 사용자 정의 클래스는 예외 클래스를 포함하는 형태로 작성하면 좋다.               
추후에 포함한 표준 예외클래스를 활용해 더욱 풍부한 오류 분석을 할 수 있게 된다.      
   
```java
public void wrapException(String input) throws MyBusinessException {
    try {
        // do something
    } catch (NumberFormatException e) {
        throw new MyBusinessException("A message that describes the error.", e, ErrorCode.INVALID_PORT_CONFIGURATION);
    }
}
```
    
# 클린코드에서의 예외처리        
클린코드에서는 '예외처리를 어떻게 하면 효율적으로 진행할 수 있을까?'에 대한 조언을 준다.   
필자가 정리한 사이트가 있으니 한 번쯤 확인 해보는 것도 좋을 것이다.   
      
[클린코드-예외처리](https://github.com/kwj1270/TIL_CleanCode/blob/master/07%20%EC%98%A4%EB%A5%98%EC%B2%98%EB%A6%AC.md)    

# 도움이 될 만한 자료들   
여태 기술했던 내용들 외에도 좋은 내용들이 있어 소개하고자합니다.      
필자도 아직, 깊게 공부한 것이 아니기에 해당 페이지에 기술하지 않았고     
추후에 더 깊게 공부하면 현재 페이지를 수정할 예정입니다.      
   
```
토비님이 알려주신 예외처리 3가지
1. 예외 복구   
2. 예외처리 회피  
3. 예외 전환     
```
     
[코딩으로 알아보는 예외처리 - yadon079님의 블로그](https://yadon079.github.io/2021/java%20study%20halle/week-09)           
[예외처리시 return - minikuma님의 노션](https://www.notion.so/9-17a778bba6ed4436ac3d7b9415b6babb)           
[커스텀 예외 생성 4가지 주의사항-  - ssonsh 님의 노션](https://www.notion.so/3565a9689f714638af34125cbb8abbe8)         
[try-with-resource 동작구조 - lee_maru님의 블로그](https://catch-me-java.tistory.com/46)     
[토비의 스프링3 예외처리 - 개발배말님의 블로그](https://blog.baesangwoo.dev/posts/java-livestudy-9week/)            
[스프링 예외 처리 - rkdals213님의 블로그](https://www.notion.so/cce3fc21976f4400aa4ed8d3fb26497b)         
[표준 예외 클래스 - youngerjesus님의 블로그](https://velog.io/@youngerjesus/%EC%9E%90%EB%B0%94-%EC%98%88%EC%99%B8-%EC%B2%98%EB%A6%AC)       
[표준 예외 클래스 - ByungJun25님의 블로그](https://github.com/ByungJun25/study/tree/main/java/whiteship-study/9week)     
[이펙티브 자바 아이템9 - kongduboo님의 깃허브](https://github.com/kongduboo/whiteship-java-study/blob/main/week9.md)        
[예외처리 비용 - leegicheol님의 블로그](https://leegicheol.github.io/whiteship-live-study/whiteship-live-study-09-exception-handling/#%EC%98%88%EC%99%B8%EC%B2%98%EB%A6%AC-%EB%B9%84%EC%9A%A9)           
      
# 참고   
[자바의 정석 - 서적](http://www.yes24.com/Product/Goods/24259565)    
[윤성우의 열혈 자바 프로그래밍 - 서적](http://www.yes24.com/Product/Goods/43755519)       
[ssonsh 님의 노션](https://www.notion.so/3565a9689f714638af34125cbb8abbe8)         
[lee_maru님의 블로그](https://catch-me-java.tistory.com/46)      
